<?xml version="1.0" ?>
<!-- =================================================================================== -->
<!-- |    This document was autogenerated by xacro from rs007n.urdf.xacro              | -->
<!-- |    EDITING THIS FILE BY HAND IS NOT RECOMMENDED                                 | -->
<!-- |    edited by hand to add Gripper :) - Mike Wise 30 Mar 2022                     | -->
<!-- |    added lines at the bottom                                                    | -->
<!-- =================================================================================== -->
<robot name="khi_rs007n_gripper">
  <transmission name="$join1_trans">
    <type>transmission_interface/SimpleTransmission</type>
    <actuator name="joint1_motor">
      <hardwareInterface>hardware_interface/PositionJointInterface</hardwareInterface>
      <mechanicalReduction>1</mechanicalReduction>
    </actuator>
    <joint name="joint1">
      <hardwareInterface>hardware_interface/PositionJointInterface</hardwareInterface>
    </joint>
  </transmission>
  <transmission name="$join2_trans">
    <type>transmission_interface/SimpleTransmission</type>
    <actuator name="joint2_motor">
      <hardwareInterface>hardware_interface/PositionJointInterface</hardwareInterface>
      <mechanicalReduction>1</mechanicalReduction>
    </actuator>
    <joint name="joint2">
      <hardwareInterface>hardware_interface/PositionJointInterface</hardwareInterface>
    </joint>
  </transmission>
  <transmission name="$join3_trans">
    <type>transmission_interface/SimpleTransmission</type>
    <actuator name="joint3_motor">
      <hardwareInterface>hardware_interface/PositionJointInterface</hardwareInterface>
      <mechanicalReduction>1</mechanicalReduction>
    </actuator>
    <joint name="joint3">
      <hardwareInterface>hardware_interface/PositionJointInterface</hardwareInterface>
    </joint>
  </transmission>
  <transmission name="$join4_trans">
    <type>transmission_interface/SimpleTransmission</type>
    <actuator name="joint4_motor">
      <hardwareInterface>hardware_interface/PositionJointInterface</hardwareInterface>
      <mechanicalReduction>1</mechanicalReduction>
    </actuator>
    <joint name="joint4">
      <hardwareInterface>hardware_interface/PositionJointInterface</hardwareInterface>
    </joint>
  </transmission>
  <transmission name="$join5_trans">
    <type>transmission_interface/SimpleTransmission</type>
    <actuator name="joint5_motor">
      <hardwareInterface>hardware_interface/PositionJointInterface</hardwareInterface>
      <mechanicalReduction>1</mechanicalReduction>
    </actuator>
    <joint name="joint5">
      <hardwareInterface>hardware_interface/PositionJointInterface</hardwareInterface>
    </joint>
  </transmission>
  <transmission name="$join6_trans">
    <type>transmission_interface/SimpleTransmission</type>
    <actuator name="joint6_motor">
      <hardwareInterface>hardware_interface/PositionJointInterface</hardwareInterface>
      <mechanicalReduction>1</mechanicalReduction>
    </actuator>
    <joint name="joint6">
      <hardwareInterface>hardware_interface/PositionJointInterface</hardwareInterface>
    </joint>
  </transmission>
  <!-- gazebo plugin -->
  <gazebo>
    <plugin filename="libgazebo_ros_control.so" name="gazebo_ros_control">
      <robotNamespace>/</robotNamespace>
    </plugin>
    <!--
    <plugin name="gazebo_ros_power_monitor_controller" filename="libgazebo_ros_power_monitor.so">
      <alwaysOn>true</alwaysOn>
      <updateRate>1.0</updateRate>
      <timeout>5</timeout>
      <powerStateTopic>power_state</powerStateTopic>
      <powerStateRate>10.0</powerStateRate>
      <fullChargeCapacity>87.78</fullChargeCapacity>     
      <dischargeRate>-474</dischargeRate>
      <chargeRate>525</chargeRate>
      <dischargeVoltage>15.52</dischargeVoltage>
      <chargeVoltage>16.41</chargeVoltage>
    </plugin>
-->
  </gazebo>
  <!-- link rviz colors -->
  <material name="White">
    <color rgba="1 1 1 1"/>
  </material>
  <material name="Black">
    <color rgba="0 0 0 1"/>
  </material>
  <!-- rs007n start -->
  <!-- Link 0 -->
  <link name="base_link">
    <visual>
      <geometry>
        <mesh filename="package://khi_rs_description/meshes/RS007N_J0.stl"/>
      </geometry>
      <material name="White"/>
      <origin rpy="0 0 0" xyz="0 0 0"/>
    </visual>
    <collision>
      <geometry>
        <mesh filename="package://khi_rs_description/meshes/RS007N_J0.stl"/>
      </geometry>
      <material name="White"/>
      <origin rpy="0 0 0" xyz="0 0 0"/>
    </collision>
    <inertial>
      <mass value="11"/>
      <inertia ixx="1.0" ixy="0.0" ixz="0.0" iyy="1.0" iyz="0.0" izz="1.0"/>
    </inertial>
  </link>
 
  
  <!-- Fix rs007n to world -->
  <link name="world"/>
  <joint name="world2base" type="fixed">
    <parent link="world"/>
    <child link="base_link"/>
    <origin rpy="0 0 0" xyz="0 0 0"/>
  </joint>
  
  <!-- Gripper Links -->

<link name="tool_link">
</link>

<link name="gripper_base">
    <visual>
      <origin rpy="0 0 0" xyz="0 0 0"/>
      <geometry>
        <mesh filename="package://khi_rs_description/Gripper1/G1_MainSupport.STL" scale = ".001 .001 .001" />
      </geometry>
    </visual>
    <collision>
      <origin rpy="0 0 0" xyz="0 0 0"/>
      <geometry>
        <mesh filename="package://khi_rs_description/Gripper1/G1_MainSupport.STL" scale = ".001 .001 .001" />
      </geometry>
    </collision>

  </link>
  <link name="servo_head">
    <visual>
      <origin rpy="0 0 0" xyz="0 0 0"/>
      <geometry>
        <mesh filename="package://khi_rs_description/Gripper1/G1_ServoHead.STL" scale = ".001 .001 .001"/>
      </geometry>
    </visual>
    <collision>
      <origin rpy="0 0 0" xyz="0 0 0"/>
      <geometry>
        <mesh filename="package://khi_rs_description/Gripper1/G1_ServoHead.STL" scale = ".001 .001 .001"/>
      </geometry>
    </collision>

  </link>

  <link name="control_rod_right">
    <visual>
      <origin rpy="0 0 0" xyz="0 0 0"/>
      <geometry>
        <mesh filename="package://khi_rs_description/Gripper1/G1_Rod.STL" scale = ".001 .001 .001"/>
      </geometry>
    </visual>
    <collision>
      <origin rpy="0 0 0" xyz="0 0 0"/>
      <geometry>
        <mesh filename="package://khi_rs_description/Gripper1/G1_Rod.STL" scale = ".001 .001 .001"/>
      </geometry>
    </collision>
  </link>

  <link name="control_rod_left">
    <visual>
      <origin rpy="0 0 0" xyz="0 0 0"/>
      <geometry>
        <mesh filename="package://khi_rs_description/Gripper1/G1_Rod.STL" scale = ".001 .001 .001"/>
      </geometry>
    </visual>
    <collision>
      <origin rpy="0 0 0" xyz="0 0 0"/>
      <geometry>
        <mesh filename="package://khi_rs_description/Gripper1/G1_Rod.STL" scale = ".001 .001 .001"/>
      </geometry>
    </collision>
  </link>

<link name="right_gripper">
    <visual>
      <origin rpy="0 0 0" xyz="0 0 0"/>
      <geometry>
        <mesh filename="package://khi_rs_description/Gripper1/G1_ClampRight.STL" scale = ".001 .001 .001"/>
      </geometry>
    </visual>
    <collision>
      <origin rpy="0 0 0" xyz="0 0 0"/>
      <geometry>
        <mesh filename="package://khi_rs_description/Gripper1/G1_ClampRight.STL" scale = ".001 .001 .001"/>
      </geometry>
    </collision>

  </link>
<link name="left_gripper">
    <visual>
      <origin rpy="0 0 0" xyz="0 0 0"/>
      <geometry>
        <mesh filename="package://khi_rs_description/Gripper1/G1_ClampLeft.STL" scale = ".001 .001 .001"/>
      </geometry>
    </visual>
    <collision>
      <origin rpy="0 0 0" xyz="0 0 0"/>
      <geometry>
        <mesh filename="package://khi_rs_description/Gripper1/G1_ClampLeft.STL" scale = ".001 .001 .001"/>
      </geometry>
    </collision>
  </link>

  <!-- Gripper Joints -->
  <joint name="hand_tool_joint" type="fixed">
    <parent link="base_link"/>
    <child link="tool_link"/>
    <origin rpy="-1.5707963268 -1.5707963268 0" xyz="0 0 0.0073"/>
  </joint>

  <joint name="hand_tool_joint" type="fixed">
    <parent link="tool_link"/>
    <child link="gripper_base"/>
    <origin rpy="1.5707 0 -1.5707" xyz="0.0246 0 -0.01475"/>
  </joint>

  <joint name="servo_head_joint" type="fixed">
    <parent link="gripper_base"/>
    <child link="servo_head"/>
    <origin rpy="0 0 0" xyz="0 0 0"/>
  </joint>
  <joint name="control_rod_left" type="fixed">
    <parent link="servo_head"/>
    <child link="control_rod_left"/>
    <origin rpy="0 0 0" xyz="0 0 0"/>
  </joint>
<joint name="control_rod_right" type="fixed">
    <parent link="servo_head"/>
    <child link="control_rod_right"/>
    <origin rpy="0 3.141 0" xyz="0 0 0"/>
  </joint>
  <joint name="gripper_joint_right" type="prismatic">
    <parent link="control_rod_right"/>
    <child link="right_gripper"/>
    <origin rpy="0 3.141 0" xyz="0 0 0"/>
    <limit effort="1" lower="-0.0257436" upper="0.0257436" velocity="1.0"/>
  </joint>
<joint name="gripper_joint_left" type="prismatic">
    <parent link="control_rod_left"/>
    <child link="left_gripper"/>
    <origin rpy="0 0 0" xyz="0 0 0"/>
    <limit effort="1" lower="-0.0257436" upper="0.0257436" velocity="1.0"/>
  </joint>
</robot>
  