<?xml version="1.0" ?>
<!-- =================================================================================== -->
<!-- |    This document was autogenerated by xacro from rs007n.urdf.xacro              | -->
<!-- |    EDITING THIS FILE BY HAND IS NOT RECOMMENDED                                 | -->
<!-- |    edited by hand to add Gripper :) - Mike Wise 30 Mar 2022                     | -->
<!-- |    added lines at the bottom                                                    | -->
<!-- =================================================================================== -->
<robot name="rs007_yaxis_gripper">
 
  <!-- link rviz colors -->
  <material name="White">
    <color rgba="1 1 1 1"/>
  </material>
  <material name="Black">
    <color rgba="0 0 0 1"/>
  </material>
  <!-- rs007n start -->
  <!-- Link 0 -->

  
  <!-- Fix rs007n to world -->
  <link name="world"/>
  <joint name="world2base" type="fixed">
    <parent link="world"/>
    <child link="tool_link"/>
    <origin rpy="0 0 0" xyz="0 0 0"/>
  </joint>
  
  <!-- Gripper Links -->

<link name="tool_link">
</link>

<link name="gripper_base">
    <visual>
      <origin rpy="0 0 0" xyz="0 0 0"/>
      <geometry>
        <mesh filename="package://khi_rs_description/Gripper1/G1_MainSupport.STL" scale = ".001 .001 .001" />
      </geometry>
    </visual>
    <collision>
      <origin rpy="0 0 0" xyz="0 0 0"/>
      <geometry>
        <mesh filename="package://khi_rs_description/Gripper1/G1_MainSupport.STL" scale = ".001 .001 .001" />
      </geometry>
    </collision>

  </link>
  <link name="servo_head">
    <visual>
      <origin rpy="0 0 0" xyz="0 0 0"/>
      <geometry>
        <mesh filename="package://khi_rs_description/Gripper1/G1_ServoHead.STL" scale = ".001 .001 .001"/>
      </geometry>
    </visual>
    <collision>
      <origin rpy="0 0 0" xyz="0 0 0"/>
      <geometry>
        <mesh filename="package://khi_rs_description/Gripper1/G1_ServoHead.STL" scale = ".001 .001 .001"/>
      </geometry>
    </collision>

  </link>

  <link name="control_rod_right">
    <visual>
      <origin rpy="0 0 0" xyz="0 0 0"/>
      <geometry>
        <mesh filename="package://khi_rs_description/Gripper1/G1_Rod.STL" scale = ".001 .001 .001"/>
      </geometry>
    </visual>
    <collision>
      <origin rpy="0 0 0" xyz="0 0 0"/>
      <geometry>
        <mesh filename="package://khi_rs_description/Gripper1/G1_Rod.STL" scale = ".001 .001 .001"/>
      </geometry>
    </collision>
  </link>

  <link name="control_rod_left">
    <visual>
      <origin rpy="0 0 0" xyz="0 0 0"/>
      <geometry>
        <mesh filename="package://khi_rs_description/Gripper1/G1_Rod.STL" scale = ".001 .001 .001"/>
      </geometry>
    </visual>
    <collision>
      <origin rpy="0 0 0" xyz="0 0 0"/>
      <geometry>
        <mesh filename="package://khi_rs_description/Gripper1/G1_Rod.STL" scale = ".001 .001 .001"/>
      </geometry>
    </collision>
  </link>

<link name="right_gripper">
    <visual>
      <origin rpy="0 0 0" xyz="0 0 0"/>
      <geometry>
        <mesh filename="package://khi_rs_description/Gripper1/G1_ClampRight.STL" scale = ".001 .001 .001"/>
      </geometry>
    </visual>
    <collision>
      <origin rpy="0 0 0" xyz="0 0 0"/>
      <geometry>
        <mesh filename="package://khi_rs_description/Gripper1/G1_ClampRight.STL" scale = ".001 .001 .001"/>
      </geometry>
    </collision>

  </link>
<link name="left_gripper">
    <visual>
      <origin rpy="0 0 0" xyz="0 0 0"/>
      <geometry>
        <mesh filename="package://khi_rs_description/Gripper1/G1_ClampLeft.STL" scale = ".001 .001 .001"/>
      </geometry>
    </visual>
    <collision>
      <origin rpy="0 0 0" xyz="0 0 0"/>
      <geometry>
        <mesh filename="package://khi_rs_description/Gripper1/G1_ClampLeft.STL" scale = ".001 .001 .001"/>
      </geometry>
    </collision>
  </link>

  <!-- Gripper Joints -->
  <joint name="hand_tool_joint" type="fixed">
    <parent link="base_link"/>
    <child link="tool_link"/>
    <origin rpy="-1.5707963268 -1.5707963268 0" xyz="0 0 0.0073"/>
  </joint>

  <joint name="hand_tool_joint" type="fixed">
    <parent link="tool_link"/>
    <child link="gripper_base"/>
    <origin rpy="1.5707 0 -1.5707" xyz="0.0246 0 -0.01475"/>
  </joint>

  <joint name="servo_head_joint" type="fixed">
    <parent link="gripper_base"/>
    <child link="servo_head"/>
    <origin rpy="0 0 0" xyz="0 0 0"/>
  </joint>
  <joint name="control_rod_left" type="fixed">
    <parent link="servo_head"/>
    <child link="control_rod_left"/>
    <origin rpy="0 0 0" xyz="0 0 0"/>
  </joint>
<joint name="control_rod_right" type="fixed">
    <parent link="servo_head"/>
    <child link="control_rod_right"/>
    <origin rpy="0 3.141 0" xyz="0 0 0"/>
  </joint>
  <joint name="gripper_joint_right" type="prismatic">
    <parent link="control_rod_right"/>
    <child link="right_gripper"/>
    <axis xyz="0 1 0" />
    <origin rpy="0 3.141 0" xyz="0 0 0"/>
    <limit effort="1" lower="-0.0257436" upper="0.0257436" velocity="1.0"/>
  </joint>
<joint name="gripper_joint_left" type="prismatic">
    <parent link="control_rod_left"/>
    <child link="left_gripper"/>
    <axis xyz="0 1 0" />   
    <origin rpy="0 0 0" xyz="0 0 0"/>
    <limit effort="2" lower="-0.0257436" upper="0.0257436" velocity="1.0"/>
  </joint>
</robot>
  